<?xml version="1.0" encoding="UTF-8"?>
<!-- Generated by org.testng.reporters.JUnitReportReporter -->
<testsuite hostname="Techno-311" failures="0" tests="36" name="io.mosip.testscripts.OtpAuthNew" time="72.236" errors="14" timestamp="31 Jan 2023 07:46:23 GMT" skipped="0">
  <testcase classname="io.mosip.testscripts.OtpAuthNew" name="auth_OTP_Auth_With_Blank_individualId_uin_neg" time="1.753">
    <error message="Failed at output validation" type="io.mosip.admin.fw.util.AdminTestException">
      <![CDATA[io.mosip.admin.fw.util.AdminTestException: Failed at output validation
	at io.mosip.testscripts.OtpAuthNew.test(OtpAuthNew.java:188)
	at java.base/jdk.internal.reflect.NativeMethodAccessorImpl.invoke0(Native Method)
	at java.base/jdk.internal.reflect.NativeMethodAccessorImpl.invoke(NativeMethodAccessorImpl.java:62)
	at java.base/jdk.internal.reflect.DelegatingMethodAccessorImpl.invoke(DelegatingMethodAccessorImpl.java:43)
	at java.base/java.lang.reflect.Method.invoke(Method.java:566)
	at org.testng.internal.MethodInvocationHelper.invokeMethod(MethodInvocationHelper.java:108)
	at org.testng.internal.Invoker.invokeMethod(Invoker.java:661)
	at org.testng.internal.Invoker.invokeTestMethod(Invoker.java:869)
	at org.testng.internal.Invoker.invokeTestMethods(Invoker.java:1193)
	at org.testng.internal.TestMethodWorker.invokeTestMethods(TestMethodWorker.java:126)
	at org.testng.internal.TestMethodWorker.run(TestMethodWorker.java:109)
	at org.testng.TestRunner.privateRun(TestRunner.java:744)
	at org.testng.TestRunner.run(TestRunner.java:602)
	at org.testng.SuiteRunner.runTest(SuiteRunner.java:380)
	at org.testng.SuiteRunner.runSequentially(SuiteRunner.java:375)
	at org.testng.SuiteRunner.privateRun(SuiteRunner.java:340)
	at org.testng.SuiteRunner.run(SuiteRunner.java:289)
	at org.testng.SuiteRunnerWorker.runSuite(SuiteRunnerWorker.java:52)
	at org.testng.SuiteRunnerWorker.run(SuiteRunnerWorker.java:86)
	at org.testng.TestNG.runSuitesSequentially(TestNG.java:1301)
	at org.testng.TestNG.runSuitesLocally(TestNG.java:1226)
	at org.testng.TestNG.runSuites(TestNG.java:1144)
	at org.testng.TestNG.run(TestNG.java:1115)
	at io.mosip.testrunner.MosipTestRunner.startTestRunner(MosipTestRunner.java:177)
	at io.mosip.testrunner.MosipTestRunner.main(MosipTestRunner.java:124)
]]>
    </error>
  </testcase> <!-- auth_OTP_Auth_With_Blank_individualId_uin_neg -->
  <testcase classname="io.mosip.testscripts.OtpAuthNew" name="auth_EkycOtp_With_invalid_uin_partner" time="1.692">
    <error message="Failed at output validation" type="io.mosip.admin.fw.util.AdminTestException">
      <![CDATA[io.mosip.admin.fw.util.AdminTestException: Failed at output validation
	at io.mosip.testscripts.OtpAuthNew.test(OtpAuthNew.java:188)
	at jdk.internal.reflect.GeneratedMethodAccessor208.invoke(Unknown Source)
	at java.base/jdk.internal.reflect.DelegatingMethodAccessorImpl.invoke(DelegatingMethodAccessorImpl.java:43)
	at java.base/java.lang.reflect.Method.invoke(Method.java:566)
	at org.testng.internal.MethodInvocationHelper.invokeMethod(MethodInvocationHelper.java:108)
	at org.testng.internal.Invoker.invokeMethod(Invoker.java:661)
	at org.testng.internal.Invoker.invokeTestMethod(Invoker.java:869)
	at org.testng.internal.Invoker.invokeTestMethods(Invoker.java:1193)
	at org.testng.internal.TestMethodWorker.invokeTestMethods(TestMethodWorker.java:126)
	at org.testng.internal.TestMethodWorker.run(TestMethodWorker.java:109)
	at org.testng.TestRunner.privateRun(TestRunner.java:744)
	at org.testng.TestRunner.run(TestRunner.java:602)
	at org.testng.SuiteRunner.runTest(SuiteRunner.java:380)
	at org.testng.SuiteRunner.runSequentially(SuiteRunner.java:375)
	at org.testng.SuiteRunner.privateRun(SuiteRunner.java:340)
	at org.testng.SuiteRunner.run(SuiteRunner.java:289)
	at org.testng.SuiteRunnerWorker.runSuite(SuiteRunnerWorker.java:52)
	at org.testng.SuiteRunnerWorker.run(SuiteRunnerWorker.java:86)
	at org.testng.TestNG.runSuitesSequentially(TestNG.java:1301)
	at org.testng.TestNG.runSuitesLocally(TestNG.java:1226)
	at org.testng.TestNG.runSuites(TestNG.java:1144)
	at org.testng.TestNG.run(TestNG.java:1115)
	at io.mosip.testrunner.MosipTestRunner.startTestRunner(MosipTestRunner.java:177)
	at io.mosip.testrunner.MosipTestRunner.main(MosipTestRunner.java:124)
]]>
    </error>
  </testcase> <!-- auth_EkycOtp_With_invalid_uin_partner -->
  <testcase classname="io.mosip.testscripts.OtpAuthNew" name="auth_OTP_Auth_With_Blank_individualId_VID_neg" time="2.029"/>
  <testcase classname="io.mosip.testscripts.OtpAuthNew" name="auth_OTP_Auth_With_Blank_transactionId_uin_Pos" time="1.619"/>
  <testcase classname="io.mosip.testscripts.OtpAuthNew" name="auth_EkycOtp_With_revoke_VID_Smoke_Pos" time="2.218">
    <error message="Failed at output validation" type="io.mosip.admin.fw.util.AdminTestException">
      <![CDATA[io.mosip.admin.fw.util.AdminTestException: Failed at output validation
	at io.mosip.testscripts.OtpAuthNew.test(OtpAuthNew.java:188)
	at jdk.internal.reflect.GeneratedMethodAccessor208.invoke(Unknown Source)
	at java.base/jdk.internal.reflect.DelegatingMethodAccessorImpl.invoke(DelegatingMethodAccessorImpl.java:43)
	at java.base/java.lang.reflect.Method.invoke(Method.java:566)
	at org.testng.internal.MethodInvocationHelper.invokeMethod(MethodInvocationHelper.java:108)
	at org.testng.internal.Invoker.invokeMethod(Invoker.java:661)
	at org.testng.internal.Invoker.invokeTestMethod(Invoker.java:869)
	at org.testng.internal.Invoker.invokeTestMethods(Invoker.java:1193)
	at org.testng.internal.TestMethodWorker.invokeTestMethods(TestMethodWorker.java:126)
	at org.testng.internal.TestMethodWorker.run(TestMethodWorker.java:109)
	at org.testng.TestRunner.privateRun(TestRunner.java:744)
	at org.testng.TestRunner.run(TestRunner.java:602)
	at org.testng.SuiteRunner.runTest(SuiteRunner.java:380)
	at org.testng.SuiteRunner.runSequentially(SuiteRunner.java:375)
	at org.testng.SuiteRunner.privateRun(SuiteRunner.java:340)
	at org.testng.SuiteRunner.run(SuiteRunner.java:289)
	at org.testng.SuiteRunnerWorker.runSuite(SuiteRunnerWorker.java:52)
	at org.testng.SuiteRunnerWorker.run(SuiteRunnerWorker.java:86)
	at org.testng.TestNG.runSuitesSequentially(TestNG.java:1301)
	at org.testng.TestNG.runSuitesLocally(TestNG.java:1226)
	at org.testng.TestNG.runSuites(TestNG.java:1144)
	at org.testng.TestNG.run(TestNG.java:1115)
	at io.mosip.testrunner.MosipTestRunner.startTestRunner(MosipTestRunner.java:177)
	at io.mosip.testrunner.MosipTestRunner.main(MosipTestRunner.java:124)
]]>
    </error>
  </testcase> <!-- auth_EkycOtp_With_revoke_VID_Smoke_Pos -->
  <testcase classname="io.mosip.testscripts.OtpAuthNew" name="auth_EkycOtp_With_Missing_individualId_uin_neg" time="1.617">
    <error message="Failed at output validation" type="io.mosip.admin.fw.util.AdminTestException">
      <![CDATA[io.mosip.admin.fw.util.AdminTestException: Failed at output validation
	at io.mosip.testscripts.OtpAuthNew.test(OtpAuthNew.java:188)
	at jdk.internal.reflect.GeneratedMethodAccessor208.invoke(Unknown Source)
	at java.base/jdk.internal.reflect.DelegatingMethodAccessorImpl.invoke(DelegatingMethodAccessorImpl.java:43)
	at java.base/java.lang.reflect.Method.invoke(Method.java:566)
	at org.testng.internal.MethodInvocationHelper.invokeMethod(MethodInvocationHelper.java:108)
	at org.testng.internal.Invoker.invokeMethod(Invoker.java:661)
	at org.testng.internal.Invoker.invokeTestMethod(Invoker.java:869)
	at org.testng.internal.Invoker.invokeTestMethods(Invoker.java:1193)
	at org.testng.internal.TestMethodWorker.invokeTestMethods(TestMethodWorker.java:126)
	at org.testng.internal.TestMethodWorker.run(TestMethodWorker.java:109)
	at org.testng.TestRunner.privateRun(TestRunner.java:744)
	at org.testng.TestRunner.run(TestRunner.java:602)
	at org.testng.SuiteRunner.runTest(SuiteRunner.java:380)
	at org.testng.SuiteRunner.runSequentially(SuiteRunner.java:375)
	at org.testng.SuiteRunner.privateRun(SuiteRunner.java:340)
	at org.testng.SuiteRunner.run(SuiteRunner.java:289)
	at org.testng.SuiteRunnerWorker.runSuite(SuiteRunnerWorker.java:52)
	at org.testng.SuiteRunnerWorker.run(SuiteRunnerWorker.java:86)
	at org.testng.TestNG.runSuitesSequentially(TestNG.java:1301)
	at org.testng.TestNG.runSuitesLocally(TestNG.java:1226)
	at org.testng.TestNG.runSuites(TestNG.java:1144)
	at org.testng.TestNG.run(TestNG.java:1115)
	at io.mosip.testrunner.MosipTestRunner.startTestRunner(MosipTestRunner.java:177)
	at io.mosip.testrunner.MosipTestRunner.main(MosipTestRunner.java:124)
]]>
    </error>
  </testcase> <!-- auth_EkycOtp_With_Missing_individualId_uin_neg -->
  <testcase classname="io.mosip.testscripts.OtpAuthNew" name="auth_EkycOtp_With_Valid_VID_Smoke_Pos" time="2.438"/>
  <testcase classname="io.mosip.testscripts.OtpAuthNew" name="auth_EkycOtp_Auth_With_Valid_UIN_Smoke" time="1.592">
    <error message="Failed at output validation" type="io.mosip.admin.fw.util.AdminTestException">
      <![CDATA[io.mosip.admin.fw.util.AdminTestException: Failed at output validation
	at io.mosip.testscripts.OtpAuthNew.test(OtpAuthNew.java:188)
	at jdk.internal.reflect.GeneratedMethodAccessor208.invoke(Unknown Source)
	at java.base/jdk.internal.reflect.DelegatingMethodAccessorImpl.invoke(DelegatingMethodAccessorImpl.java:43)
	at java.base/java.lang.reflect.Method.invoke(Method.java:566)
	at org.testng.internal.MethodInvocationHelper.invokeMethod(MethodInvocationHelper.java:108)
	at org.testng.internal.Invoker.invokeMethod(Invoker.java:661)
	at org.testng.internal.Invoker.invokeTestMethod(Invoker.java:869)
	at org.testng.internal.Invoker.invokeTestMethods(Invoker.java:1193)
	at org.testng.internal.TestMethodWorker.invokeTestMethods(TestMethodWorker.java:126)
	at org.testng.internal.TestMethodWorker.run(TestMethodWorker.java:109)
	at org.testng.TestRunner.privateRun(TestRunner.java:744)
	at org.testng.TestRunner.run(TestRunner.java:602)
	at org.testng.SuiteRunner.runTest(SuiteRunner.java:380)
	at org.testng.SuiteRunner.runSequentially(SuiteRunner.java:375)
	at org.testng.SuiteRunner.privateRun(SuiteRunner.java:340)
	at org.testng.SuiteRunner.run(SuiteRunner.java:289)
	at org.testng.SuiteRunnerWorker.runSuite(SuiteRunnerWorker.java:52)
	at org.testng.SuiteRunnerWorker.run(SuiteRunnerWorker.java:86)
	at org.testng.TestNG.runSuitesSequentially(TestNG.java:1301)
	at org.testng.TestNG.runSuitesLocally(TestNG.java:1226)
	at org.testng.TestNG.runSuites(TestNG.java:1144)
	at org.testng.TestNG.run(TestNG.java:1115)
	at io.mosip.testrunner.MosipTestRunner.startTestRunner(MosipTestRunner.java:177)
	at io.mosip.testrunner.MosipTestRunner.main(MosipTestRunner.java:124)
]]>
    </error>
  </testcase> <!-- auth_EkycOtp_Auth_With_Valid_UIN_Smoke -->
  <testcase classname="io.mosip.testscripts.OtpAuthNew" name="auth_EkycOtp_With_Blank_individualId_uin_neg" time="1.603">
    <error message="Failed at output validation" type="io.mosip.admin.fw.util.AdminTestException">
      <![CDATA[io.mosip.admin.fw.util.AdminTestException: Failed at output validation
	at io.mosip.testscripts.OtpAuthNew.test(OtpAuthNew.java:188)
	at jdk.internal.reflect.GeneratedMethodAccessor208.invoke(Unknown Source)
	at java.base/jdk.internal.reflect.DelegatingMethodAccessorImpl.invoke(DelegatingMethodAccessorImpl.java:43)
	at java.base/java.lang.reflect.Method.invoke(Method.java:566)
	at org.testng.internal.MethodInvocationHelper.invokeMethod(MethodInvocationHelper.java:108)
	at org.testng.internal.Invoker.invokeMethod(Invoker.java:661)
	at org.testng.internal.Invoker.invokeTestMethod(Invoker.java:869)
	at org.testng.internal.Invoker.invokeTestMethods(Invoker.java:1193)
	at org.testng.internal.TestMethodWorker.invokeTestMethods(TestMethodWorker.java:126)
	at org.testng.internal.TestMethodWorker.run(TestMethodWorker.java:109)
	at org.testng.TestRunner.privateRun(TestRunner.java:744)
	at org.testng.TestRunner.run(TestRunner.java:602)
	at org.testng.SuiteRunner.runTest(SuiteRunner.java:380)
	at org.testng.SuiteRunner.runSequentially(SuiteRunner.java:375)
	at org.testng.SuiteRunner.privateRun(SuiteRunner.java:340)
	at org.testng.SuiteRunner.run(SuiteRunner.java:289)
	at org.testng.SuiteRunnerWorker.runSuite(SuiteRunnerWorker.java:52)
	at org.testng.SuiteRunnerWorker.run(SuiteRunnerWorker.java:86)
	at org.testng.TestNG.runSuitesSequentially(TestNG.java:1301)
	at org.testng.TestNG.runSuitesLocally(TestNG.java:1226)
	at org.testng.TestNG.runSuites(TestNG.java:1144)
	at org.testng.TestNG.run(TestNG.java:1115)
	at io.mosip.testrunner.MosipTestRunner.startTestRunner(MosipTestRunner.java:177)
	at io.mosip.testrunner.MosipTestRunner.main(MosipTestRunner.java:124)
]]>
    </error>
  </testcase> <!-- auth_EkycOtp_With_Blank_individualId_uin_neg -->
  <testcase classname="io.mosip.testscripts.OtpAuthNew" name="auth_OTP_Auth_With_different_transactionId_uin_neg" time="1.795"/>
  <testcase classname="io.mosip.testscripts.OtpAuthNew" name="auth_OTP_Auth_With_Missing_Optional_Field_individualIdType_VID" time="2.075"/>
  <testcase classname="io.mosip.testscripts.OtpAuthNew" name="auth_EkycOtp_With_Different_transaction_id_VID_Pos" time="2.754"/>
  <testcase classname="io.mosip.testscripts.OtpAuthNew" name="auth_OTP_Auth_With_Invalid_individualId_UIN_neg" time="1.921">
    <error message="Failed at output validation" type="io.mosip.admin.fw.util.AdminTestException">
      <![CDATA[io.mosip.admin.fw.util.AdminTestException: Failed at output validation
	at io.mosip.testscripts.OtpAuthNew.test(OtpAuthNew.java:188)
	at java.base/jdk.internal.reflect.NativeMethodAccessorImpl.invoke0(Native Method)
	at java.base/jdk.internal.reflect.NativeMethodAccessorImpl.invoke(NativeMethodAccessorImpl.java:62)
	at java.base/jdk.internal.reflect.DelegatingMethodAccessorImpl.invoke(DelegatingMethodAccessorImpl.java:43)
	at java.base/java.lang.reflect.Method.invoke(Method.java:566)
	at org.testng.internal.MethodInvocationHelper.invokeMethod(MethodInvocationHelper.java:108)
	at org.testng.internal.Invoker.invokeMethod(Invoker.java:661)
	at org.testng.internal.Invoker.invokeTestMethod(Invoker.java:869)
	at org.testng.internal.Invoker.invokeTestMethods(Invoker.java:1193)
	at org.testng.internal.TestMethodWorker.invokeTestMethods(TestMethodWorker.java:126)
	at org.testng.internal.TestMethodWorker.run(TestMethodWorker.java:109)
	at org.testng.TestRunner.privateRun(TestRunner.java:744)
	at org.testng.TestRunner.run(TestRunner.java:602)
	at org.testng.SuiteRunner.runTest(SuiteRunner.java:380)
	at org.testng.SuiteRunner.runSequentially(SuiteRunner.java:375)
	at org.testng.SuiteRunner.privateRun(SuiteRunner.java:340)
	at org.testng.SuiteRunner.run(SuiteRunner.java:289)
	at org.testng.SuiteRunnerWorker.runSuite(SuiteRunnerWorker.java:52)
	at org.testng.SuiteRunnerWorker.run(SuiteRunnerWorker.java:86)
	at org.testng.TestNG.runSuitesSequentially(TestNG.java:1301)
	at org.testng.TestNG.runSuitesLocally(TestNG.java:1226)
	at org.testng.TestNG.runSuites(TestNG.java:1144)
	at org.testng.TestNG.run(TestNG.java:1115)
	at io.mosip.testrunner.MosipTestRunner.startTestRunner(MosipTestRunner.java:177)
	at io.mosip.testrunner.MosipTestRunner.main(MosipTestRunner.java:124)
]]>
    </error>
  </testcase> <!-- auth_OTP_Auth_With_Invalid_individualId_UIN_neg -->
  <testcase classname="io.mosip.testscripts.OtpAuthNew" name="auth_EkycOtp_With_Invalid_transactionId_uin_Pos" time="1.592">
    <error message="Failed at output validation" type="io.mosip.admin.fw.util.AdminTestException">
      <![CDATA[io.mosip.admin.fw.util.AdminTestException: Failed at output validation
	at io.mosip.testscripts.OtpAuthNew.test(OtpAuthNew.java:188)
	at jdk.internal.reflect.GeneratedMethodAccessor208.invoke(Unknown Source)
	at java.base/jdk.internal.reflect.DelegatingMethodAccessorImpl.invoke(DelegatingMethodAccessorImpl.java:43)
	at java.base/java.lang.reflect.Method.invoke(Method.java:566)
	at org.testng.internal.MethodInvocationHelper.invokeMethod(MethodInvocationHelper.java:108)
	at org.testng.internal.Invoker.invokeMethod(Invoker.java:661)
	at org.testng.internal.Invoker.invokeTestMethod(Invoker.java:869)
	at org.testng.internal.Invoker.invokeTestMethods(Invoker.java:1193)
	at org.testng.internal.TestMethodWorker.invokeTestMethods(TestMethodWorker.java:126)
	at org.testng.internal.TestMethodWorker.run(TestMethodWorker.java:109)
	at org.testng.TestRunner.privateRun(TestRunner.java:744)
	at org.testng.TestRunner.run(TestRunner.java:602)
	at org.testng.SuiteRunner.runTest(SuiteRunner.java:380)
	at org.testng.SuiteRunner.runSequentially(SuiteRunner.java:375)
	at org.testng.SuiteRunner.privateRun(SuiteRunner.java:340)
	at org.testng.SuiteRunner.run(SuiteRunner.java:289)
	at org.testng.SuiteRunnerWorker.runSuite(SuiteRunnerWorker.java:52)
	at org.testng.SuiteRunnerWorker.run(SuiteRunnerWorker.java:86)
	at org.testng.TestNG.runSuitesSequentially(TestNG.java:1301)
	at org.testng.TestNG.runSuitesLocally(TestNG.java:1226)
	at org.testng.TestNG.runSuites(TestNG.java:1144)
	at org.testng.TestNG.run(TestNG.java:1115)
	at io.mosip.testrunner.MosipTestRunner.startTestRunner(MosipTestRunner.java:177)
	at io.mosip.testrunner.MosipTestRunner.main(MosipTestRunner.java:124)
]]>
    </error>
  </testcase> <!-- auth_EkycOtp_With_Invalid_transactionId_uin_Pos -->
  <testcase classname="io.mosip.testscripts.OtpAuthNew" name="auth_EkycOtp_With_Different_transaction_id_uin_Pos" time="1.894">
    <error message="Failed at output validation" type="io.mosip.admin.fw.util.AdminTestException">
      <![CDATA[io.mosip.admin.fw.util.AdminTestException: Failed at output validation
	at io.mosip.testscripts.OtpAuthNew.test(OtpAuthNew.java:188)
	at jdk.internal.reflect.GeneratedMethodAccessor208.invoke(Unknown Source)
	at java.base/jdk.internal.reflect.DelegatingMethodAccessorImpl.invoke(DelegatingMethodAccessorImpl.java:43)
	at java.base/java.lang.reflect.Method.invoke(Method.java:566)
	at org.testng.internal.MethodInvocationHelper.invokeMethod(MethodInvocationHelper.java:108)
	at org.testng.internal.Invoker.invokeMethod(Invoker.java:661)
	at org.testng.internal.Invoker.invokeTestMethod(Invoker.java:869)
	at org.testng.internal.Invoker.invokeTestMethods(Invoker.java:1193)
	at org.testng.internal.TestMethodWorker.invokeTestMethods(TestMethodWorker.java:126)
	at org.testng.internal.TestMethodWorker.run(TestMethodWorker.java:109)
	at org.testng.TestRunner.privateRun(TestRunner.java:744)
	at org.testng.TestRunner.run(TestRunner.java:602)
	at org.testng.SuiteRunner.runTest(SuiteRunner.java:380)
	at org.testng.SuiteRunner.runSequentially(SuiteRunner.java:375)
	at org.testng.SuiteRunner.privateRun(SuiteRunner.java:340)
	at org.testng.SuiteRunner.run(SuiteRunner.java:289)
	at org.testng.SuiteRunnerWorker.runSuite(SuiteRunnerWorker.java:52)
	at org.testng.SuiteRunnerWorker.run(SuiteRunnerWorker.java:86)
	at org.testng.TestNG.runSuitesSequentially(TestNG.java:1301)
	at org.testng.TestNG.runSuitesLocally(TestNG.java:1226)
	at org.testng.TestNG.runSuites(TestNG.java:1144)
	at org.testng.TestNG.run(TestNG.java:1115)
	at io.mosip.testrunner.MosipTestRunner.startTestRunner(MosipTestRunner.java:177)
	at io.mosip.testrunner.MosipTestRunner.main(MosipTestRunner.java:124)
]]>
    </error>
  </testcase> <!-- auth_EkycOtp_With_Different_transaction_id_uin_Pos -->
  <testcase classname="io.mosip.testscripts.OtpAuthNew" name="auth_OTP_Auth_With_Invalid_transactionId_uin_Pos" time="1.907"/>
  <testcase classname="io.mosip.testscripts.OtpAuthNew" name="auth_EkycOtp_With_Blank_transactionId_uin_Pos" time="1.600">
    <error message="Failed at output validation" type="io.mosip.admin.fw.util.AdminTestException">
      <![CDATA[io.mosip.admin.fw.util.AdminTestException: Failed at output validation
	at io.mosip.testscripts.OtpAuthNew.test(OtpAuthNew.java:188)
	at jdk.internal.reflect.GeneratedMethodAccessor208.invoke(Unknown Source)
	at java.base/jdk.internal.reflect.DelegatingMethodAccessorImpl.invoke(DelegatingMethodAccessorImpl.java:43)
	at java.base/java.lang.reflect.Method.invoke(Method.java:566)
	at org.testng.internal.MethodInvocationHelper.invokeMethod(MethodInvocationHelper.java:108)
	at org.testng.internal.Invoker.invokeMethod(Invoker.java:661)
	at org.testng.internal.Invoker.invokeTestMethod(Invoker.java:869)
	at org.testng.internal.Invoker.invokeTestMethods(Invoker.java:1193)
	at org.testng.internal.TestMethodWorker.invokeTestMethods(TestMethodWorker.java:126)
	at org.testng.internal.TestMethodWorker.run(TestMethodWorker.java:109)
	at org.testng.TestRunner.privateRun(TestRunner.java:744)
	at org.testng.TestRunner.run(TestRunner.java:602)
	at org.testng.SuiteRunner.runTest(SuiteRunner.java:380)
	at org.testng.SuiteRunner.runSequentially(SuiteRunner.java:375)
	at org.testng.SuiteRunner.privateRun(SuiteRunner.java:340)
	at org.testng.SuiteRunner.run(SuiteRunner.java:289)
	at org.testng.SuiteRunnerWorker.runSuite(SuiteRunnerWorker.java:52)
	at org.testng.SuiteRunnerWorker.run(SuiteRunnerWorker.java:86)
	at org.testng.TestNG.runSuitesSequentially(TestNG.java:1301)
	at org.testng.TestNG.runSuitesLocally(TestNG.java:1226)
	at org.testng.TestNG.runSuites(TestNG.java:1144)
	at org.testng.TestNG.run(TestNG.java:1115)
	at io.mosip.testrunner.MosipTestRunner.startTestRunner(MosipTestRunner.java:177)
	at io.mosip.testrunner.MosipTestRunner.main(MosipTestRunner.java:124)
]]>
    </error>
  </testcase> <!-- auth_EkycOtp_With_Blank_transactionId_uin_Pos -->
  <testcase classname="io.mosip.testscripts.OtpAuthNew" name="auth_EkycOtp_With_Invalid_individualIdType_VID_Pos" time="2.719"/>
  <testcase classname="io.mosip.testscripts.OtpAuthNew" name="auth_OTP_Auth_With_Missing_individualId_VID_neg" time="2.010"/>
  <testcase classname="io.mosip.testscripts.OtpAuthNew" name="auth_EkycOtp_With_Missing_individualId_VID_neg" time="1.713"/>
  <testcase classname="io.mosip.testscripts.OtpAuthNew" name="auth_OTP_Auth_With_Valid_UIN_Smoke_Pos" time="1.869"/>
  <testcase classname="io.mosip.testscripts.OtpAuthNew" name="auth_OTP_Auth_With_Blank_transactionId_VID_Pos" time="2.183"/>
  <testcase classname="io.mosip.testscripts.OtpAuthNew" name="auth_EkycOtp_With_Blank_individualId_VID_neg" time="1.679"/>
  <testcase classname="io.mosip.testscripts.OtpAuthNew" name="auth_EkycOtp_With_Blank_individualIdType_VID_Pos" time="2.813"/>
  <testcase classname="io.mosip.testscripts.OtpAuthNew" name="auth_EkycOtp_With_Invalid_individualId_uin_neg" time="1.651">
    <error message="Failed at output validation" type="io.mosip.admin.fw.util.AdminTestException">
      <![CDATA[io.mosip.admin.fw.util.AdminTestException: Failed at output validation
	at io.mosip.testscripts.OtpAuthNew.test(OtpAuthNew.java:188)
	at jdk.internal.reflect.GeneratedMethodAccessor208.invoke(Unknown Source)
	at java.base/jdk.internal.reflect.DelegatingMethodAccessorImpl.invoke(DelegatingMethodAccessorImpl.java:43)
	at java.base/java.lang.reflect.Method.invoke(Method.java:566)
	at org.testng.internal.MethodInvocationHelper.invokeMethod(MethodInvocationHelper.java:108)
	at org.testng.internal.Invoker.invokeMethod(Invoker.java:661)
	at org.testng.internal.Invoker.invokeTestMethod(Invoker.java:869)
	at org.testng.internal.Invoker.invokeTestMethods(Invoker.java:1193)
	at org.testng.internal.TestMethodWorker.invokeTestMethods(TestMethodWorker.java:126)
	at org.testng.internal.TestMethodWorker.run(TestMethodWorker.java:109)
	at org.testng.TestRunner.privateRun(TestRunner.java:744)
	at org.testng.TestRunner.run(TestRunner.java:602)
	at org.testng.SuiteRunner.runTest(SuiteRunner.java:380)
	at org.testng.SuiteRunner.runSequentially(SuiteRunner.java:375)
	at org.testng.SuiteRunner.privateRun(SuiteRunner.java:340)
	at org.testng.SuiteRunner.run(SuiteRunner.java:289)
	at org.testng.SuiteRunnerWorker.runSuite(SuiteRunnerWorker.java:52)
	at org.testng.SuiteRunnerWorker.run(SuiteRunnerWorker.java:86)
	at org.testng.TestNG.runSuitesSequentially(TestNG.java:1301)
	at org.testng.TestNG.runSuitesLocally(TestNG.java:1226)
	at org.testng.TestNG.runSuites(TestNG.java:1144)
	at org.testng.TestNG.run(TestNG.java:1115)
	at io.mosip.testrunner.MosipTestRunner.startTestRunner(MosipTestRunner.java:177)
	at io.mosip.testrunner.MosipTestRunner.main(MosipTestRunner.java:124)
]]>
    </error>
  </testcase> <!-- auth_EkycOtp_With_Invalid_individualId_uin_neg -->
  <testcase classname="io.mosip.testscripts.OtpAuthNew" name="auth_EkycOtp_With_Invalid_individualId_VID_neg" time="1.612"/>
  <testcase classname="io.mosip.testscripts.OtpAuthNew" name="auth_OTP_Auth_With_Invalid_transactionId_VID_Pos" time="2.146"/>
  <testcase classname="io.mosip.testscripts.OtpAuthNew" name="auth_OTP_Auth_With_Invalid_individualId_VID_neg" time="1.884"/>
  <testcase classname="io.mosip.testscripts.OtpAuthNew" name="auth_EkycOtp_With_Blank_transactionId_VID_Pos" time="2.698"/>
  <testcase classname="io.mosip.testscripts.OtpAuthNew" name="auth_OTP_Auth_With_revoke_VID_Smoke_Pos" time="2.097">
    <error message="Failed at output validation" type="io.mosip.admin.fw.util.AdminTestException">
      <![CDATA[io.mosip.admin.fw.util.AdminTestException: Failed at output validation
	at io.mosip.testscripts.OtpAuthNew.test(OtpAuthNew.java:188)
	at java.base/jdk.internal.reflect.NativeMethodAccessorImpl.invoke0(Native Method)
	at java.base/jdk.internal.reflect.NativeMethodAccessorImpl.invoke(NativeMethodAccessorImpl.java:62)
	at java.base/jdk.internal.reflect.DelegatingMethodAccessorImpl.invoke(DelegatingMethodAccessorImpl.java:43)
	at java.base/java.lang.reflect.Method.invoke(Method.java:566)
	at org.testng.internal.MethodInvocationHelper.invokeMethod(MethodInvocationHelper.java:108)
	at org.testng.internal.Invoker.invokeMethod(Invoker.java:661)
	at org.testng.internal.Invoker.invokeTestMethod(Invoker.java:869)
	at org.testng.internal.Invoker.invokeTestMethods(Invoker.java:1193)
	at org.testng.internal.TestMethodWorker.invokeTestMethods(TestMethodWorker.java:126)
	at org.testng.internal.TestMethodWorker.run(TestMethodWorker.java:109)
	at org.testng.TestRunner.privateRun(TestRunner.java:744)
	at org.testng.TestRunner.run(TestRunner.java:602)
	at org.testng.SuiteRunner.runTest(SuiteRunner.java:380)
	at org.testng.SuiteRunner.runSequentially(SuiteRunner.java:375)
	at org.testng.SuiteRunner.privateRun(SuiteRunner.java:340)
	at org.testng.SuiteRunner.run(SuiteRunner.java:289)
	at org.testng.SuiteRunnerWorker.runSuite(SuiteRunnerWorker.java:52)
	at org.testng.SuiteRunnerWorker.run(SuiteRunnerWorker.java:86)
	at org.testng.TestNG.runSuitesSequentially(TestNG.java:1301)
	at org.testng.TestNG.runSuitesLocally(TestNG.java:1226)
	at org.testng.TestNG.runSuites(TestNG.java:1144)
	at org.testng.TestNG.run(TestNG.java:1115)
	at io.mosip.testrunner.MosipTestRunner.startTestRunner(MosipTestRunner.java:177)
	at io.mosip.testrunner.MosipTestRunner.main(MosipTestRunner.java:124)
]]>
    </error>
  </testcase> <!-- auth_OTP_Auth_With_revoke_VID_Smoke_Pos -->
  <testcase classname="io.mosip.testscripts.OtpAuthNew" name="auth_OTP_Auth_With_Invalid_uin_partner" time="1.582">
    <error message="Failed at output validation" type="io.mosip.admin.fw.util.AdminTestException">
      <![CDATA[io.mosip.admin.fw.util.AdminTestException: Failed at output validation
	at io.mosip.testscripts.OtpAuthNew.test(OtpAuthNew.java:188)
	at jdk.internal.reflect.GeneratedMethodAccessor208.invoke(Unknown Source)
	at java.base/jdk.internal.reflect.DelegatingMethodAccessorImpl.invoke(DelegatingMethodAccessorImpl.java:43)
	at java.base/java.lang.reflect.Method.invoke(Method.java:566)
	at org.testng.internal.MethodInvocationHelper.invokeMethod(MethodInvocationHelper.java:108)
	at org.testng.internal.Invoker.invokeMethod(Invoker.java:661)
	at org.testng.internal.Invoker.invokeTestMethod(Invoker.java:869)
	at org.testng.internal.Invoker.invokeTestMethods(Invoker.java:1193)
	at org.testng.internal.TestMethodWorker.invokeTestMethods(TestMethodWorker.java:126)
	at org.testng.internal.TestMethodWorker.run(TestMethodWorker.java:109)
	at org.testng.TestRunner.privateRun(TestRunner.java:744)
	at org.testng.TestRunner.run(TestRunner.java:602)
	at org.testng.SuiteRunner.runTest(SuiteRunner.java:380)
	at org.testng.SuiteRunner.runSequentially(SuiteRunner.java:375)
	at org.testng.SuiteRunner.privateRun(SuiteRunner.java:340)
	at org.testng.SuiteRunner.run(SuiteRunner.java:289)
	at org.testng.SuiteRunnerWorker.runSuite(SuiteRunnerWorker.java:52)
	at org.testng.SuiteRunnerWorker.run(SuiteRunnerWorker.java:86)
	at org.testng.TestNG.runSuitesSequentially(TestNG.java:1301)
	at org.testng.TestNG.runSuitesLocally(TestNG.java:1226)
	at org.testng.TestNG.runSuites(TestNG.java:1144)
	at org.testng.TestNG.run(TestNG.java:1115)
	at io.mosip.testrunner.MosipTestRunner.startTestRunner(MosipTestRunner.java:177)
	at io.mosip.testrunner.MosipTestRunner.main(MosipTestRunner.java:124)
]]>
    </error>
  </testcase> <!-- auth_OTP_Auth_With_Invalid_uin_partner -->
  <testcase classname="io.mosip.testscripts.OtpAuthNew" name="auth_OTP_Auth_With_Blank_individualIdType_VID_Pos" time="2.122"/>
  <testcase classname="io.mosip.testscripts.OtpAuthNew" name="auth_EkycOtp_With_Invalid_transactionId_VID_Pos" time="3.133"/>
  <testcase classname="io.mosip.testscripts.OtpAuthNew" name="auth_OTP_Auth_With_Valid_VID_Smoke_Pos" time="2.334"/>
  <testcase classname="io.mosip.testscripts.OtpAuthNew" name="auth_OTP_Auth_With_Invalid_individualIdType_VID_neg" time="2.183"/>
  <testcase classname="io.mosip.testscripts.OtpAuthNew" name="auth_OTP_Auth_With_Missing_individualId_uin_neg" time="1.709">
    <error message="Failed at output validation" type="io.mosip.admin.fw.util.AdminTestException">
      <![CDATA[io.mosip.admin.fw.util.AdminTestException: Failed at output validation
	at io.mosip.testscripts.OtpAuthNew.test(OtpAuthNew.java:188)
	at java.base/jdk.internal.reflect.NativeMethodAccessorImpl.invoke0(Native Method)
	at java.base/jdk.internal.reflect.NativeMethodAccessorImpl.invoke(NativeMethodAccessorImpl.java:62)
	at java.base/jdk.internal.reflect.DelegatingMethodAccessorImpl.invoke(DelegatingMethodAccessorImpl.java:43)
	at java.base/java.lang.reflect.Method.invoke(Method.java:566)
	at org.testng.internal.MethodInvocationHelper.invokeMethod(MethodInvocationHelper.java:108)
	at org.testng.internal.Invoker.invokeMethod(Invoker.java:661)
	at org.testng.internal.Invoker.invokeTestMethod(Invoker.java:869)
	at org.testng.internal.Invoker.invokeTestMethods(Invoker.java:1193)
	at org.testng.internal.TestMethodWorker.invokeTestMethods(TestMethodWorker.java:126)
	at org.testng.internal.TestMethodWorker.run(TestMethodWorker.java:109)
	at org.testng.TestRunner.privateRun(TestRunner.java:744)
	at org.testng.TestRunner.run(TestRunner.java:602)
	at org.testng.SuiteRunner.runTest(SuiteRunner.java:380)
	at org.testng.SuiteRunner.runSequentially(SuiteRunner.java:375)
	at org.testng.SuiteRunner.privateRun(SuiteRunner.java:340)
	at org.testng.SuiteRunner.run(SuiteRunner.java:289)
	at org.testng.SuiteRunnerWorker.runSuite(SuiteRunnerWorker.java:52)
	at org.testng.SuiteRunnerWorker.run(SuiteRunnerWorker.java:86)
	at org.testng.TestNG.runSuitesSequentially(TestNG.java:1301)
	at org.testng.TestNG.runSuitesLocally(TestNG.java:1226)
	at org.testng.TestNG.runSuites(TestNG.java:1144)
	at org.testng.TestNG.run(TestNG.java:1115)
	at io.mosip.testrunner.MosipTestRunner.startTestRunner(MosipTestRunner.java:177)
	at io.mosip.testrunner.MosipTestRunner.main(MosipTestRunner.java:124)
]]>
    </error>
  </testcase> <!-- auth_OTP_Auth_With_Missing_individualId_uin_neg -->
</testsuite> <!-- io.mosip.testscripts.OtpAuthNew -->
